[2019-06-08 19:40:42]
Traceback (most recent call last):
  File "smash.py", line 372, in <module>
    run_gui()
  File "smash.py", line 346, in run_gui
    os.system('python3', __file__)
TypeError: system() takes at most 1 argument (2 given)

[2019-06-06 23:50:39]
KeyboardInterrupt

[2019-06-06 23:47:52]
KeyboardInterrupt

[2019-06-06 23:05:54]
Traceback (most recent call last):
  File "smash.py", line 367, in <module>
    run_gui()
  File "smash.py", line 334, in run_gui
    root.mainloop()
  File "/usr/lib/python3.7/tkinter/__init__.py", line 1283, in mainloop
    self.tk.mainloop(n)
  File "/usr/lib/python3.7/tkinter/__init__.py", line 1700, in __call__
    def __call__(self, *args):
KeyboardInterrupt

[2019-06-06 22:59:09]
Traceback (most recent call last):
  File "smash.py", line 367, in <module>
    run_gui()
  File "smash.py", line 334, in run_gui
    root.mainloop()
  File "/usr/lib/python3.7/tkinter/__init__.py", line 1283, in mainloop
    self.tk.mainloop(n)
  File "/usr/lib/python3.7/tkinter/__init__.py", line 1700, in __call__
    def __call__(self, *args):
KeyboardInterrupt

[2019-06-06 22:39:03]
Traceback (most recent call last):
  File "smash.py", line 367, in <module>
    run_gui()
  File "smash.py", line 334, in run_gui
    root.mainloop()
  File "/usr/lib/python3.7/tkinter/__init__.py", line 1283, in mainloop
    self.tk.mainloop(n)
  File "/usr/lib/python3.7/tkinter/__init__.py", line 1700, in __call__
    def __call__(self, *args):
KeyboardInterrupt

[2019-06-06 20:26:02]
Traceback (most recent call last):
  File "smash.py", line 367, in <module>
    run_gui()
  File "smash.py", line 334, in run_gui
    root.mainloop()
  File "/usr/lib/python3.7/tkinter/__init__.py", line 1283, in mainloop
    self.tk.mainloop(n)
  File "/usr/lib/python3.7/tkinter/__init__.py", line 1700, in __call__
    def __call__(self, *args):
KeyboardInterrupt

[2019-06-05 21:43:22]
Traceback (most recent call last):
  File "smash.py", line 11, in <module>
    import smash_watcher
  File "/home/colorsolid/smashframes/smash/smash_reader/smash_watcher.py", line 191
    )}
    ^
SyntaxError: invalid syntax

[2019-06-05 21:43:20]
Traceback (most recent call last):
  File "smash.py", line 366, in <module>
    run_gui()
  File "smash.py", line 333, in run_gui
    root.mainloop()
  File "/usr/lib/python3.7/tkinter/__init__.py", line 1283, in mainloop
    self.tk.mainloop(n)
  File "/usr/lib/python3.7/tkinter/__init__.py", line 1700, in __call__
    def __call__(self, *args):
KeyboardInterrupt

[2019-06-05 21:30:28]
Traceback (most recent call last):
  File "tests.py", line 409, in <module>
    test_game_data()
  File "tests.py", line 34, in test_game_data
    ut.filter_game_data(game, 1)
  File "/home/colorsolid/smashframes/smash/smash_reader/smash_utility.py", line 357, in filter_game_data
    simple_game['cancelled'] = game['cancelled']
KeyError: 'cancelled'

[2019-06-05 19:23:05]
Traceback (most recent call last):
  File "tests.py", line 409, in <module>
    test_game_data()
  File "tests.py", line 34, in test_game_data
    ut.filter_game_data(game, 1)
  File "/home/colorsolid/smashframes/smash/smash_reader/smash_utility.py", line 348, in filter_game_data
    for key in keys:
RuntimeError: dictionary changed size during iteration

[2019-06-05 19:22:05]
Traceback (most recent call last):
  File "tests.py", line 409, in <module>
    test_game_data()
  File "tests.py", line 34, in test_game_data
    ut.filter_game_data(game, 1)
  File "/home/colorsolid/smashframes/smash/smash_reader/smash_utility.py", line 348, in filter_game_data
    for key in keys:
RuntimeError: dictionary changed size during iteration

[2019-06-05 18:01:34]
Traceback (most recent call last):
  File "tests.py", line 409, in <module>
    test_game_data()
  File "tests.py", line 34, in test_game_data
    ut.post_game_data(game, 1)
  File "/home/colorsolid/smashframes/smash/smash_reader/smash_utility.py", line 348, in post_game_data
    for key in keys:
RuntimeError: dictionary changed size during iteration

[2019-06-05 18:01:05]
Traceback (most recent call last):
  File "tests.py", line 409, in <module>
    test_game_data()
  File "tests.py", line 34, in test_game_data
    ut.post_game_data(game, 1)
  File "/home/colorsolid/smashframes/smash/smash_reader/smash_utility.py", line 347, in post_game_data
    for key in player:
RuntimeError: dictionary changed size during iteration

[2019-06-05 17:59:39]
Traceback (most recent call last):
  File "tests.py", line 409, in <module>
    test_game_data()
  File "tests.py", line 34, in test_game_data
    ut.post_game_data(game, 1)
  File "/home/colorsolid/smashframes/smash/smash_reader/smash_utility.py", line 348, in post_game_data
    game['players'].append(player)
KeyError: 'players'

[2019-06-05 17:59:21]
Traceback (most recent call last):
  File "tests.py", line 409, in <module>
    test_game_data()
  File "tests.py", line 34, in test_game_data
    ut.post_game_data(game, 1)
  File "/home/colorsolid/smashframes/smash/smash_reader/smash_utility.py", line 348, in post_game_data
    players.append(player)
NameError: name 'players' is not defined

[2019-06-04 22:50:14]
Traceback (most recent call last):
  File "<stdin>", line 1, in <module>
  File "/home/colorsolid/smashframes/smash/smash_reader/smash_utility.py", line 348, in post_data
    r = requests.post(url = URL, json = DATA)
NameError: name 'requests' is not defined

[2019-06-04 22:22:54]
KeyboardInterrupt

[2019-05-25 21:03:16]
Traceback (most recent call last):
  File "<stdin>", line 1, in <module>
ModuleNotFoundError: No module named 'urllib2'

[2019-05-25 20:57:53]
Traceback (most recent call last):
  File "<stdin>", line 1, in <module>
  File "/home/colorsolid/smashframes/smash/smash_reader/tests.py", line 34, in req
    r = requests.post(url = URL, data = DATA)
  File "/home/colorsolid/%HOME/.virtualenvs/reader/lib/python3.7/site-packages/requests/api.py", line 116, in post
    return request('post', url, data=data, json=json, **kwargs)
  File "/home/colorsolid/%HOME/.virtualenvs/reader/lib/python3.7/site-packages/requests/api.py", line 60, in request
    return session.request(method=method, url=url, **kwargs)
  File "/home/colorsolid/%HOME/.virtualenvs/reader/lib/python3.7/site-packages/requests/sessions.py", line 533, in request
    resp = self.send(prep, **send_kwargs)
  File "/home/colorsolid/%HOME/.virtualenvs/reader/lib/python3.7/site-packages/requests/sessions.py", line 640, in send
    adapter = self.get_adapter(url=request.url)
  File "/home/colorsolid/%HOME/.virtualenvs/reader/lib/python3.7/site-packages/requests/sessions.py", line 731, in get_adapter
    raise InvalidSchema("No connection adapters were found for '%s'" % url)
requests.exceptions.InvalidSchema: No connection adapters were found for 'localhost:8000/reader_info'

[2019-05-25 20:57:13]
Traceback (most recent call last):
  File "<stdin>", line 1, in <module>
  File "/home/colorsolid/smashframes/smash/smash_reader/tests.py", line 21, in <module>
    from PIL import Image, ImageChops, ImageDraw, ImageGrab
  File "/home/colorsolid/%HOME/.virtualenvs/reader/lib/python3.7/site-packages/PIL/ImageGrab.py", line 22, in <module>
    raise ImportError("ImageGrab is macOS and Windows only")
ImportError: ImageGrab is macOS and Windows only

[2019-05-19 20:51:47]
Traceback (most recent call last):
  File "smash.py", line 365, in <module>
    run_gui()
  File "smash.py", line 332, in run_gui
    root.mainloop()
  File "/usr/lib/python3.7/tkinter/__init__.py", line 1283, in mainloop
    self.tk.mainloop(n)
  File "/usr/lib/python3.7/tkinter/__init__.py", line 1700, in __call__
    def __call__(self, *args):
KeyboardInterrupt

[2019-05-19 15:40:37]
Traceback (most recent call last):
  File "smash.py", line 365, in <module>
    run_gui()
  File "smash.py", line 332, in run_gui
    root.mainloop()
  File "/usr/lib/python3.7/tkinter/__init__.py", line 1283, in mainloop
    self.tk.mainloop(n)
  File "/usr/lib/python3.7/tkinter/__init__.py", line 1700, in __call__
    def __call__(self, *args):
KeyboardInterrupt

[2019-05-19 15:39:12]
Traceback (most recent call last):
  File "smash.py", line 365, in <module>
    run_gui()
  File "smash.py", line 332, in run_gui
    root.mainloop()
  File "/usr/lib/python3.7/tkinter/__init__.py", line 1283, in mainloop
    self.tk.mainloop(n)
  File "/usr/lib/python3.7/tkinter/__init__.py", line 1700, in __call__
    def __call__(self, *args):
KeyboardInterrupt

[2019-05-09 21:47:22]
Traceback (most recent call last):
  File "C:\Users\cunss\OneDrive\Documents\Projects\smash\reader\smash_reader\smash.py", line 361, in <module>
    run_gui(settings)
NameError: name 'settings' is not defined

[2019-05-09 21:35:37]
Traceback (most recent call last):
  File "C:\Users\cunss\OneDrive\Documents\Projects\smash\reader\smash_reader\smash.py", line 358, in <module>
    ut.output = settings['utility_output']
KeyError: 'utility_output'

[2019-05-09 21:34:16]
Traceback (most recent call last):
  File "C:\Users\cunss\OneDrive\Documents\Projects\smash\reader\smash_reader\smash.py", line 356, in <module>
    settings = ut.load_settings()
  File "C:\Users\cunss\OneDrive\Documents\Projects\smash\reader\smash_reader\smash_utility.py", line 396, in load_settings
    save_settings(settings)
  File "C:\Users\cunss\OneDrive\Documents\Projects\smash\reader\smash_reader\smash_utility.py", line 381, in save_settings
    json.dump(path, settings)
  File "C:\Users\cunss\AppData\Local\Programs\Python\Python37\lib\json\__init__.py", line 180, in dump
    fp.write(chunk)
AttributeError: 'dict' object has no attribute 'write'

[2019-05-09 21:33:28]
Traceback (most recent call last):
  File "C:\Users\cunss\OneDrive\Documents\Projects\smash\reader\smash_reader\smash.py", line 356, in <module>
    settings = ut.load_settings()
  File "C:\Users\cunss\OneDrive\Documents\Projects\smash\reader\smash_reader\smash_utility.py", line 396, in load_settings
    save_settings(settings)
  File "C:\Users\cunss\OneDrive\Documents\Projects\smash\reader\smash_reader\smash_utility.py", line 381, in save_settings
    json.dump(settings, path)
  File "C:\Users\cunss\AppData\Local\Programs\Python\Python37\lib\json\__init__.py", line 180, in dump
    fp.write(chunk)
AttributeError: 'str' object has no attribute 'write'

[2019-05-09 21:33:02]
Traceback (most recent call last):
  File "C:\Users\cunss\OneDrive\Documents\Projects\smash\reader\smash_reader\smash.py", line 356, in <module>
    settings = ut.load_settings()
  File "C:\Users\cunss\OneDrive\Documents\Projects\smash\reader\smash_reader\smash_utility.py", line 388, in load_settings
    settings = json.load(infile)
  File "C:\Users\cunss\AppData\Local\Programs\Python\Python37\lib\json\__init__.py", line 296, in load
    parse_constant=parse_constant, object_pairs_hook=object_pairs_hook, **kw)
  File "C:\Users\cunss\AppData\Local\Programs\Python\Python37\lib\json\__init__.py", line 348, in loads
    return _default_decoder.decode(s)
  File "C:\Users\cunss\AppData\Local\Programs\Python\Python37\lib\json\decoder.py", line 337, in decode
    obj, end = self.raw_decode(s, idx=_w(s, 0).end())
  File "C:\Users\cunss\AppData\Local\Programs\Python\Python37\lib\json\decoder.py", line 355, in raw_decode
    raise JSONDecodeError("Expecting value", s, err.value) from None
json.decoder.JSONDecodeError: Expecting value: line 1 column 1 (char 0)

[2019-05-09 21:32:21]
Traceback (most recent call last):
  File "C:\Users\cunss\OneDrive\Documents\Projects\smash\reader\smash_reader\smash.py", line 356, in <module>
    settings = ut.load_settings()
  File "C:\Users\cunss\OneDrive\Documents\Projects\smash\reader\smash_reader\smash_utility.py", line 395, in load_settings
    save_settings(settings)
  File "C:\Users\cunss\OneDrive\Documents\Projects\smash\reader\smash_reader\smash_utility.py", line 380, in save_settings
    json.dump(settings, path)
  File "C:\Users\cunss\AppData\Local\Programs\Python\Python37\lib\json\__init__.py", line 180, in dump
    fp.write(chunk)
AttributeError: 'str' object has no attribute 'write'

[2019-05-09 21:11:17]
Traceback (most recent call last):
  File "C:\Users\cunss\OneDrive\Documents\Projects\smash\reader\smash_reader\smash.py", line 17, in <module>
    print(test)
NameError: name 'test' is not defined

[2019-05-08 23:54:51]
Traceback (most recent call last):
  File "C:\Users\cunss\OneDrive\Documents\Projects\smash\reader\smash_reader\smash.py", line 17, in <module>
    print(test)
NameError: name 'test' is not defined

[2019-05-08 23:53:11]
Traceback (most recent call last):
  File "C:\Users\cunss\OneDrive\Documents\Projects\smash\reader\smash_reader\smash.py", line 17, in <module>
    print(test)
NameError: name 'test' is not defined

[2019-05-08 23:47:49]
Traceback (most recent call last):
  File "C:\Users\cunss\OneDrive\Documents\Projects\smash\reader\smash_reader\smash.py", line 17, in <module>
    print(test)
NameError: name 'test' is not defined

[2019-05-08 23:47:26]
Traceback (most recent call last):
  File "C:\Users\cunss\OneDrive\Documents\Projects\smash\reader\smash_reader\smash.py", line 17, in <module>
    print(test)
NameError: name 'test' is not defined

[2019-05-08 23:31:47]
Traceback (most recent call last):
  File "C:\Users\cunss\OneDrive\Documents\Projects\smash\reader\smash_reader\smash.py", line 9, in <module>
    import smash_watcher
  File "C:\Users\cunss\OneDrive\Documents\Projects\smash\reader\smash_reader\smash_watcher.py", line 15, in <module>
    print(test)
NameError: name 'test' is not defined

[2019-05-08 23:30:31]
Traceback (most recent call last):
  File "C:\Users\cunss\OneDrive\Documents\Projects\smash\reader\smash_reader\smash.py", line 352, in <module>
    print(test)
NameError: name 'test' is not defined

